C:\Users\dnietot\AppData\Local\Programs\Python\Python313\Lib\site-packages\pytest_asyncio\plugin.py:217: PytestDeprecationWarning: The configuration option "asyncio_default_fixture_loop_scope" is unset.
The event loop scope for asynchronous fixtures will default to the fixture caching scope. Future versions of pytest-asyncio will default the loop scope for asynchronous fixtures to function scope. Set the default fixture loop scope explicitly in order to avoid unexpected behavior in the future. Valid fixture loop scopes are: "function", "class", "module", "package", "session"

  warnings.warn(PytestDeprecationWarning(_DEFAULT_FIXTURE_LOOP_SCOPE_UNSET))
============================= test session starts =============================
platform win32 -- Python 3.13.1, pytest-8.3.5, pluggy-1.5.0
rootdir: C:\Users\dnietot\desktop\Proyecto\Proyecto_GrupoAsd
configfile: pytest.ini
plugins: anyio-4.8.0, asyncio-0.26.0, cov-6.1.1, httpx-0.35.0, mock-3.14.0
asyncio: mode=Mode.STRICT, asyncio_default_fixture_loop_scope=None, asyncio_default_test_loop_scope=function
collected 42 items / 6 errors

=================================== ERRORS ====================================
________________ ERROR collecting Test/test_activity_router.py ________________
Test\test_activity_router.py:3: in <module>
    from  Routers.activity_router import router
Routers\activity_router.py:4: in <module>
    from Elastic.index_dispatcher import send_document
Elastic\index_dispatcher.py:1: in <module>
    from Elastic.elastic_client import es
Elastic\elastic_client.py:11: in <module>
    es = Elasticsearch(
..\..\..\AppData\Local\Programs\Python\Python313\Lib\site-packages\elasticsearch\_sync\client\__init__.py:427: in __init__
    self._headers = resolve_auth_headers(
..\..\..\AppData\Local\Programs\Python\Python313\Lib\site-packages\elasticsearch\_sync\client\_base.py:132: in resolve_auth_headers
    f"Basic {_base64_auth_header(resolved_basic_auth)}"
..\..\..\AppData\Local\Programs\Python\Python313\Lib\site-packages\elasticsearch\_sync\client\utils.py:259: in _base64_auth_header
    return base64.b64encode(to_bytes(":".join(auth_value))).decode("ascii")
..\..\..\AppData\Local\Programs\Python\Python313\Lib\site-packages\elasticsearch\compat.py:34: in to_bytes
    return x.encode(encoding)
E   UnicodeEncodeError: 'ascii' codec can't encode character '\xf1' in position 19: ordinal not in range(128)
_______________ ERROR collecting Test/test_index_dispatcher.py ________________
..\..\..\AppData\Local\Programs\Python\Python313\Lib\site-packages\pytest_asyncio\plugin.py:754: in _patched_collect
    module = collector.obj
..\..\..\AppData\Local\Programs\Python\Python313\Lib\site-packages\_pytest\python.py:284: in obj
    self._obj = obj = self._getobj()
..\..\..\AppData\Local\Programs\Python\Python313\Lib\site-packages\_pytest\python.py:546: in _getobj
    return importtestmodule(self.path, self.config)
..\..\..\AppData\Local\Programs\Python\Python313\Lib\site-packages\_pytest\python.py:493: in importtestmodule
    mod = import_path(
..\..\..\AppData\Local\Programs\Python\Python313\Lib\site-packages\_pytest\pathlib.py:587: in import_path
    importlib.import_module(module_name)
..\..\..\AppData\Local\Programs\Python\Python313\Lib\importlib\__init__.py:88: in import_module
    return _bootstrap._gcd_import(name[level:], package, level)
<frozen importlib._bootstrap>:1387: in _gcd_import
    ???
<frozen importlib._bootstrap>:1360: in _find_and_load
    ???
<frozen importlib._bootstrap>:1331: in _find_and_load_unlocked
    ???
<frozen importlib._bootstrap>:935: in _load_unlocked
    ???
..\..\..\AppData\Local\Programs\Python\Python313\Lib\site-packages\_pytest\assertion\rewrite.py:185: in exec_module
    exec(co, module.__dict__)
Test\test_index_dispatcher.py:6: in <module>
    from Elastic.index_dispatcher import send_document  # Ajusta esto a tu estructura de imports
Elastic\index_dispatcher.py:1: in <module>
    from Elastic.elastic_client import es
Elastic\elastic_client.py:11: in <module>
    es = Elasticsearch(
..\..\..\AppData\Local\Programs\Python\Python313\Lib\site-packages\elasticsearch\_sync\client\__init__.py:427: in __init__
    self._headers = resolve_auth_headers(
..\..\..\AppData\Local\Programs\Python\Python313\Lib\site-packages\elasticsearch\_sync\client\_base.py:132: in resolve_auth_headers
    f"Basic {_base64_auth_header(resolved_basic_auth)}"
..\..\..\AppData\Local\Programs\Python\Python313\Lib\site-packages\elasticsearch\_sync\client\utils.py:259: in _base64_auth_header
    return base64.b64encode(to_bytes(":".join(auth_value))).decode("ascii")
..\..\..\AppData\Local\Programs\Python\Python313\Lib\site-packages\elasticsearch\compat.py:34: in to_bytes
    return x.encode(encoding)
E   UnicodeEncodeError: 'ascii' codec can't encode character '\xf1' in position 19: ordinal not in range(128)
___________________ ERROR collecting Test/test_pr_router.py ___________________
..\..\..\AppData\Local\Programs\Python\Python313\Lib\site-packages\pytest_asyncio\plugin.py:754: in _patched_collect
    module = collector.obj
..\..\..\AppData\Local\Programs\Python\Python313\Lib\site-packages\_pytest\python.py:284: in obj
    self._obj = obj = self._getobj()
..\..\..\AppData\Local\Programs\Python\Python313\Lib\site-packages\_pytest\python.py:546: in _getobj
    return importtestmodule(self.path, self.config)
..\..\..\AppData\Local\Programs\Python\Python313\Lib\site-packages\_pytest\python.py:493: in importtestmodule
    mod = import_path(
..\..\..\AppData\Local\Programs\Python\Python313\Lib\site-packages\_pytest\pathlib.py:587: in import_path
    importlib.import_module(module_name)
..\..\..\AppData\Local\Programs\Python\Python313\Lib\importlib\__init__.py:88: in import_module
    return _bootstrap._gcd_import(name[level:], package, level)
<frozen importlib._bootstrap>:1387: in _gcd_import
    ???
<frozen importlib._bootstrap>:1360: in _find_and_load
    ???
<frozen importlib._bootstrap>:1331: in _find_and_load_unlocked
    ???
<frozen importlib._bootstrap>:935: in _load_unlocked
    ???
..\..\..\AppData\Local\Programs\Python\Python313\Lib\site-packages\_pytest\assertion\rewrite.py:185: in exec_module
    exec(co, module.__dict__)
Test\test_pr_router.py:4: in <module>
    from Routers.pr_router import router
Routers\pr_router.py:4: in <module>
    from Elastic.bulk_dispatcher import send_bulk_documents
Elastic\bulk_dispatcher.py:2: in <module>
    from Elastic.elastic_client import es
Elastic\elastic_client.py:11: in <module>
    es = Elasticsearch(
..\..\..\AppData\Local\Programs\Python\Python313\Lib\site-packages\elasticsearch\_sync\client\__init__.py:427: in __init__
    self._headers = resolve_auth_headers(
..\..\..\AppData\Local\Programs\Python\Python313\Lib\site-packages\elasticsearch\_sync\client\_base.py:132: in resolve_auth_headers
    f"Basic {_base64_auth_header(resolved_basic_auth)}"
..\..\..\AppData\Local\Programs\Python\Python313\Lib\site-packages\elasticsearch\_sync\client\utils.py:259: in _base64_auth_header
    return base64.b64encode(to_bytes(":".join(auth_value))).decode("ascii")
..\..\..\AppData\Local\Programs\Python\Python313\Lib\site-packages\elasticsearch\compat.py:34: in to_bytes
    return x.encode(encoding)
E   UnicodeEncodeError: 'ascii' codec can't encode character '\xf1' in position 19: ordinal not in range(128)
_____________ ERROR collecting Test/test_repo_activity_router.py ______________
..\..\..\AppData\Local\Programs\Python\Python313\Lib\site-packages\pytest_asyncio\plugin.py:754: in _patched_collect
    module = collector.obj
..\..\..\AppData\Local\Programs\Python\Python313\Lib\site-packages\_pytest\python.py:284: in obj
    self._obj = obj = self._getobj()
..\..\..\AppData\Local\Programs\Python\Python313\Lib\site-packages\_pytest\python.py:546: in _getobj
    return importtestmodule(self.path, self.config)
..\..\..\AppData\Local\Programs\Python\Python313\Lib\site-packages\_pytest\python.py:493: in importtestmodule
    mod = import_path(
..\..\..\AppData\Local\Programs\Python\Python313\Lib\site-packages\_pytest\pathlib.py:587: in import_path
    importlib.import_module(module_name)
..\..\..\AppData\Local\Programs\Python\Python313\Lib\importlib\__init__.py:88: in import_module
    return _bootstrap._gcd_import(name[level:], package, level)
<frozen importlib._bootstrap>:1387: in _gcd_import
    ???
<frozen importlib._bootstrap>:1360: in _find_and_load
    ???
<frozen importlib._bootstrap>:1331: in _find_and_load_unlocked
    ???
<frozen importlib._bootstrap>:935: in _load_unlocked
    ???
..\..\..\AppData\Local\Programs\Python\Python313\Lib\site-packages\_pytest\assertion\rewrite.py:185: in exec_module
    exec(co, module.__dict__)
Test\test_repo_activity_router.py:5: in <module>
    from Routers.repo_activity_router import router
Routers\repo_activity_router.py:6: in <module>
    from Elastic.index_dispatcher import send_document
Elastic\index_dispatcher.py:1: in <module>
    from Elastic.elastic_client import es
Elastic\elastic_client.py:11: in <module>
    es = Elasticsearch(
..\..\..\AppData\Local\Programs\Python\Python313\Lib\site-packages\elasticsearch\_sync\client\__init__.py:427: in __init__
    self._headers = resolve_auth_headers(
..\..\..\AppData\Local\Programs\Python\Python313\Lib\site-packages\elasticsearch\_sync\client\_base.py:132: in resolve_auth_headers
    f"Basic {_base64_auth_header(resolved_basic_auth)}"
..\..\..\AppData\Local\Programs\Python\Python313\Lib\site-packages\elasticsearch\_sync\client\utils.py:259: in _base64_auth_header
    return base64.b64encode(to_bytes(":".join(auth_value))).decode("ascii")
..\..\..\AppData\Local\Programs\Python\Python313\Lib\site-packages\elasticsearch\compat.py:34: in to_bytes
    return x.encode(encoding)
E   UnicodeEncodeError: 'ascii' codec can't encode character '\xf1' in position 19: ordinal not in range(128)
________________ ERROR collecting Test/test_template_router.py ________________
..\..\..\AppData\Local\Programs\Python\Python313\Lib\site-packages\pytest_asyncio\plugin.py:754: in _patched_collect
    module = collector.obj
..\..\..\AppData\Local\Programs\Python\Python313\Lib\site-packages\_pytest\python.py:284: in obj
    self._obj = obj = self._getobj()
..\..\..\AppData\Local\Programs\Python\Python313\Lib\site-packages\_pytest\python.py:546: in _getobj
    return importtestmodule(self.path, self.config)
..\..\..\AppData\Local\Programs\Python\Python313\Lib\site-packages\_pytest\python.py:493: in importtestmodule
    mod = import_path(
..\..\..\AppData\Local\Programs\Python\Python313\Lib\site-packages\_pytest\pathlib.py:587: in import_path
    importlib.import_module(module_name)
..\..\..\AppData\Local\Programs\Python\Python313\Lib\importlib\__init__.py:88: in import_module
    return _bootstrap._gcd_import(name[level:], package, level)
<frozen importlib._bootstrap>:1387: in _gcd_import
    ???
<frozen importlib._bootstrap>:1360: in _find_and_load
    ???
<frozen importlib._bootstrap>:1331: in _find_and_load_unlocked
    ???
<frozen importlib._bootstrap>:935: in _load_unlocked
    ???
..\..\..\AppData\Local\Programs\Python\Python313\Lib\site-packages\_pytest\assertion\rewrite.py:185: in exec_module
    exec(co, module.__dict__)
Test\test_template_router.py:5: in <module>
    from Routers import template_router
Routers\template_router.py:4: in <module>
    from Elastic.index_dispatcher import send_document
Elastic\index_dispatcher.py:1: in <module>
    from Elastic.elastic_client import es
Elastic\elastic_client.py:11: in <module>
    es = Elasticsearch(
..\..\..\AppData\Local\Programs\Python\Python313\Lib\site-packages\elasticsearch\_sync\client\__init__.py:427: in __init__
    self._headers = resolve_auth_headers(
..\..\..\AppData\Local\Programs\Python\Python313\Lib\site-packages\elasticsearch\_sync\client\_base.py:132: in resolve_auth_headers
    f"Basic {_base64_auth_header(resolved_basic_auth)}"
..\..\..\AppData\Local\Programs\Python\Python313\Lib\site-packages\elasticsearch\_sync\client\utils.py:259: in _base64_auth_header
    return base64.b64encode(to_bytes(":".join(auth_value))).decode("ascii")
..\..\..\AppData\Local\Programs\Python\Python313\Lib\site-packages\elasticsearch\compat.py:34: in to_bytes
    return x.encode(encoding)
E   UnicodeEncodeError: 'ascii' codec can't encode character '\xf1' in position 19: ordinal not in range(128)
__________________ ERROR collecting Test/test_user_router.py __________________
..\..\..\AppData\Local\Programs\Python\Python313\Lib\site-packages\pytest_asyncio\plugin.py:754: in _patched_collect
    module = collector.obj
..\..\..\AppData\Local\Programs\Python\Python313\Lib\site-packages\_pytest\python.py:284: in obj
    self._obj = obj = self._getobj()
..\..\..\AppData\Local\Programs\Python\Python313\Lib\site-packages\_pytest\python.py:546: in _getobj
    return importtestmodule(self.path, self.config)
..\..\..\AppData\Local\Programs\Python\Python313\Lib\site-packages\_pytest\python.py:493: in importtestmodule
    mod = import_path(
..\..\..\AppData\Local\Programs\Python\Python313\Lib\site-packages\_pytest\pathlib.py:587: in import_path
    importlib.import_module(module_name)
..\..\..\AppData\Local\Programs\Python\Python313\Lib\importlib\__init__.py:88: in import_module
    return _bootstrap._gcd_import(name[level:], package, level)
<frozen importlib._bootstrap>:1387: in _gcd_import
    ???
<frozen importlib._bootstrap>:1360: in _find_and_load
    ???
<frozen importlib._bootstrap>:1331: in _find_and_load_unlocked
    ???
<frozen importlib._bootstrap>:935: in _load_unlocked
    ???
..\..\..\AppData\Local\Programs\Python\Python313\Lib\site-packages\_pytest\assertion\rewrite.py:185: in exec_module
    exec(co, module.__dict__)
Test\test_user_router.py:4: in <module>
    from Routers.user_rputer import router
Routers\user_rputer.py:4: in <module>
    from Elastic.index_dispatcher import send_document
Elastic\index_dispatcher.py:1: in <module>
    from Elastic.elastic_client import es
Elastic\elastic_client.py:11: in <module>
    es = Elasticsearch(
..\..\..\AppData\Local\Programs\Python\Python313\Lib\site-packages\elasticsearch\_sync\client\__init__.py:427: in __init__
    self._headers = resolve_auth_headers(
..\..\..\AppData\Local\Programs\Python\Python313\Lib\site-packages\elasticsearch\_sync\client\_base.py:132: in resolve_auth_headers
    f"Basic {_base64_auth_header(resolved_basic_auth)}"
..\..\..\AppData\Local\Programs\Python\Python313\Lib\site-packages\elasticsearch\_sync\client\utils.py:259: in _base64_auth_header
    return base64.b64encode(to_bytes(":".join(auth_value))).decode("ascii")
..\..\..\AppData\Local\Programs\Python\Python313\Lib\site-packages\elasticsearch\compat.py:34: in to_bytes
    return x.encode(encoding)
E   UnicodeEncodeError: 'ascii' codec can't encode character '\xf1' in position 19: ordinal not in range(128)
=========================== short test summary info ===========================
ERROR Test/test_activity_router.py - UnicodeEncodeError: 'ascii' codec can't ...
ERROR Test/test_index_dispatcher.py - UnicodeEncodeError: 'ascii' codec can't...
ERROR Test/test_pr_router.py - UnicodeEncodeError: 'ascii' codec can't encode...
ERROR Test/test_repo_activity_router.py - UnicodeEncodeError: 'ascii' codec c...
ERROR Test/test_template_router.py - UnicodeEncodeError: 'ascii' codec can't ...
ERROR Test/test_user_router.py - UnicodeEncodeError: 'ascii' codec can't enco...
!!!!!!!!!!!!!!!!!!! Interrupted: 6 errors during collection !!!!!!!!!!!!!!!!!!!
============================== 6 errors in 5.19s ==============================
